Workbook

Sheet Monthly
A2: Selected Indicators | B2: 40179 | C2: 40210 | D2: 40238 | E2: 40269 | F2: 40299 | G2: 40330 | H2: 40360 | I2: 40391 | J2: 40422 | K2: 40452 | L2: 40483 | M2: 40513 | N2: 40544 | O2: 40575 | P2: 40603 | Q2: 40634 | R2: 40664 | S2: 40695 | T2: 40725 | U2: 40756 | V2: 40787 | W2: 40817 | X2: 40848 | Y2: 40878 | Z2: 40909 | AA2: 40940 | AB2: 40969 | AC2: 41000 | AD2: 41030 | AE2: 41061 | AF2: 41091 | AG2: 41122 | AH2: 41153 | AI2: 41183 | AJ2: 41214 | AK2: 41244 | AL2: 41275 | AM2: 41306 | AN2: 41334 | AO2: 41365 | AP2: 41395 | AQ2: 41426 | AR2: 41456 | AS2: 41487 | AT2: 41518 | AU2: 41548 | AV2: 41579 | AW2: 41609 | AX2: 41640 | AY2: 41671 | AZ2: 41699 | BA2: 41730 | BB2: 41760 | BC2: 41791 | BD2: 41821 | BE2: 41852 | BF2: 41883 | BG2: 41913 | BH2: 41944 | BI2: 41974 | BJ2: 42005 | BK2: 42036 | BL2: 42064 | BM2: 42095 | BN2: 42125 | BO2: 42156 | BP2: 42186 | BQ2: 42217 | BR2: 42248 | BS2: 42278 | BT2: 42309 | BU2: 42339 | BV2: 42370 | BW2: 42401 | BX2: 42430 | BY2: 42461 | BZ2: 42491 | CA2: 42522 | CB2: 42552 | CC2: 42583 | CD2: 42614 | CE2: 42644 | CF2: 42675 | CG2: 42705 | CH2: 42736 | CI2: 42767 | CJ2: 42795 | CK2: 42826 | CL2: 42856 | CM2: 42887 | CN2: 42917 | CO2: 42948 | CP2: 42979 | CQ2: 43009 | CR2: 43040 | CS2: 43070 | CT2: 43101 | CU2: 43132 | CV2: 43160 | CW2: 43191 | CX2: 43221 | CY2: 43252 | CZ2: 43282 | DA2: 43313 | DB2: 43344 | DC2: 43374 | DD2: 43405 | DE2: 43435 | DF2: 43466 | DG2: 43497 | DH2: 43525 | DI2: 43556 | DJ2: 43586 | DK2: 43617 | DL2: 43647 | DM2: 43678 | DN2: 43709 | DO2: 43739 | DP2: 43770 | DQ2: 43800 | DR2: 43831 | DS2: 43862 | DT2: 43891 | DU2: 43922 | DV2: 43952 | DW2: 43983 | DX2: 44013 | DY2: 44044 | DZ2: 44075 | EA2: 44105 | EB2: 44136 | EC2: 44166 | ED2: 44197 | EE2: 44228 | EF2: 44256 | EG2: 44287 | EH2: 44317 | EI2: 44348 | EJ2: 44378 | EK2: 44409 | EL2: 44440 | EM2: 44470 | EN2: 44501 | EO2: 44531 | EP2: 44562 | EQ2: 44593 | ER2: 44621 | ES2: 44652 | ET2: 44682 | EU2: 44713 | EV2: 44743 | EW2: 44774 | EX2: 44805 | EY2: 44835 | EZ2: 44866 | FA2: 44896 | FB2: 44927 | FC2: 44958 | FD2: 44986 | FE2: 45017 | FF2: 45047 | FG2: 45078 | FH2: 45108 | FI2: 45139 | FJ2: 45170 | FK2: 45200 | FL2: 45231 | FM2: 45261 | FN2: 45292 | FO2: 45323 | FP2: 45352 | FQ2: 45383
A3: Agriculture
A4: Horticulture Exports (MT) | V4: 15658 | W4: 17553 | X4: 17277 | Y4: 16145 | Z4: 14974 | AA4: 16053.4 | AB4: 18967 | AC4: 17407.7 | AD4: 17026.9 | AE4: 15271.1 | AF4: 17348.8 | AG4: 15868.9 | AH4: 16505.7 | AI4: 19708.4 | AJ4: 18347.3 | AK4: 18249.5 | AL4: 18397.71 | AM4: 21575.57 | AN4: 19814.19 | AO4: 19793.26 | AP4: 17135.04 | AQ4: 15180.85 | AR4: 15193.36 | AS4: 15005.36 | AT4: 17588.9 | AU4: 20291.73 | AV4: 17689.28 | AW4: 16165.4 | FR4: Addition
A5: Horticulture Exports (Ksh. Million) | V5: 6744.5 | W5: 9508.3 | X5: 6646.6 | Y5: 8914.5 | Z5: 8720.6 | AA5: 6725.7 | AB5: 6514.9 | AC5: 6317 | AD5: 6012.6 | AE5: 6227 | AF5: 7813.3 | AG5: 5825.3 | AH5: 7566.6 | AI5: 11366.8 | AJ5: 7741.9 | AK5: 9036.1 | AL5: 9071.28 | AM5: 9198.55 | AN5: 7061.08 | AO5: 5229.1 | AP5: 5924.23 | AQ5: 6995.59 | AR5: 4970.51 | AS5: 6304.29 | AT5: 5036.17 | AU5: 9117.9 | AV5: 7290.41 | AW5: 7182.38 | FR5: Addition
A6: Cut Flowers Exports (MT) | N6: 8607.2 | O6: 9516.1 | P6: 9608.3 | Q6: 11742.1 | R6: 10066.7 | S6: 8405.3 | T6: 7987.9 | U6: 7998.3 | V6: 8103.7 | W6: 9626.1 | X6: 9533.5 | Y6: 8755.1 | Z6: 9125.6 | AA6: 10126.8 | AB6: 10177.8 | AC6: 9092.5 | AD6: 9200.8 | AE6: 7058.2 | AF6: 7297.9 | AG6: 7772 | AH6: 8448.9 | AI6: 10248.3 | AJ6: 10111.2 | AK6: 9646.2 | AL6: 9485.35 | AM6: 11108.66 | AN6: 10610.98 | AO6: 8648.77 | AP6: 9470.87 | AQ6: 6853.26 | AR6: 7030.4 | AS6: 6592.11 | AT6: 6592.11 | AU6: 10019.8 | AV6: 9104.86 | AW6: 8261.52 | AX6: 8986.93 | AY6: 11514.26 | AZ6: 10669.29 | BA6: 10822 | BB6: 10769.79 | BC6: 9057.56 | BD6: 8315.83 | BE6: 7608.92 | BF6: 9647.76 | BG6: 9443.82 | BH6: 9615.63 | BI6: 8312 | BJ6: 10345.89 | BK6: 12650.72 | BL6: 11830.68 | BM6: 10873.73 | BN6: 10848.12 | BO6: 7648.16 | BP6: 7957.57 | BQ6: 8204.58 | BR6: 10538.09 | BS6: 11377.75 | BT6: 10218.62 | BU6: 10331.34 | BV6: 10016.45 | BW6: 13717.4 | BX6: 12378.88 | BY6: 12320.47 | BZ6: 11641.17 | CA6: 8904.29 | CB6: 7920.62 | CC6: 9284.47 | CD6: 10605.34 | CE6: 12542.75 | CF6: 12098.36 | CG6: 12228.15 | CH6: 12847.7 | CI6: 15576.94 | CJ6: 14394.77 | CK6: 13620.42 | CL6: 16093.2 | CM6: 12245.53 | CN6: 10163.25 | CO6: 11734.28 | CP6: 12727.64 | CQ6: 14568.45 | CR6: 12222.3 | CS6: 13766.7 | CT6: 15941.08 | CU6: 17501.03 | CV6: 14686.27 | CW6: 12833.44 | CX6: 13329.46 | CY6: 9617.48 | CZ6: 9794.81 | DA6: 11560.38 | DB6: 12854.01 | DC6: 15319.05 | DD6: 14862.36 | DE6: 12927.72 | DF6: 15585.32 | DG6: 17865.75 | DH6: 16463.44 | DI6: 15581.04 | DJ6: 15337.77 | DK6: 11744.03 | DL6: 11074.2 | DM6: 12599.63 | DN6: 14155.64 | DO6: 15105.53 | DP6: 15365.86 | DQ6: 12841.07 | DR6: 14649.06 | DS6: 17562.69 | DT6: 10438.01 | DU6: 7989.61 | DV6: 10215.07 | DW6: 9373.96 | DX6: 10928.56 | DY6: 11497.87 | DZ6: 12877.96 | EA6: 14480.22 | EB6: 12960.27 | EC6: 13060.27 | ED6: 15169.04 | EE6: 17411.9 | EF6: 17589.01 | EG6: 16473.23 | EH6: 13545.31 | EI6: 12786.28 | EJ6: 9687.18 | EK6: 19842.63 | EL6: 21584.94 | EM6: 24382.26 | EN6: 23410.82 | EO6: 18253.3 | EP6: 11360.35 | EQ6: 721998.61 | ER6: 1421655.8 | ES6: 10297.15 | ET6: 715547.18 | EU6: 8801.29 | EV6: 8425.5 | EW6: 6649.04 | EX6: 1417539.2 | EY6: 8971.1 | EZ6: 10221.18 | FA6: 11089.1 | FB6: 13414.72 | FC6: 14965.1 | FD6: 14728.41 | FE6: 14356.47 | FF6: 13451.99 | FG6: 11977.38 | FH6: 989.69 | FI6: 179.56 | FJ6: 178.48 | FK6: 14504.15 | FL6: 12841.88 | FM6: 4684.61 | FR6: Addition
A7: Cut Flowers Exports (Ksh Million) | N7: 4894.3 | O7: 5218.4 | P7: 4468.3 | Q7: 4462 | R7: 4940.7 | S7: 3858.3 | T7: 3482.1 | U7: 4297.7 | V7: 4786.8 | W7: 7203.4 | X7: 4382.5 | Y7: 6840.5 | Z7: 7225.9 | AA7: 5347.3 | AB7: 4672.7 | AC7: 4208.3 | AD7: 4255.9 | AE7: 3572.4 | AF7: 5337.2 | AG7: 3669.6 | AH7: 5588.7 | AI7: 8991.9 | AJ7: 5521.1 | AK7: 6571.4 | AL7: 6767.17 | AM7: 7275.06 | AN7: 4830.12 | AO7: 3076.23 | AP7: 4107.84 | AQ7: 4284.81 | AR7: 3083.21 | AS7: 4085.44 | AT7: 3017.82 | AU7: 6068.16 | AV7: 4327.86 | AW7: 5051.94 | AX7: 6094.76 | AY7: 6062.53 | AZ7: 7884.11 | BA7: 4442.72 | BB7: 5561.13 | BC7: 4549.28 | BD7: 4048.39 | BE7: 2870.3 | BF7: 3368.19 | BG7: 5429.03 | BH7: 5943.21 | BI7: 3639.42 | BJ7: 4379.46 | BK7: 6117.18 | BL7: 8515.11 | BM7: 4303.7 | BN7: 4431.88 | BO7: 3244.36 | BP7: 6362.96 | BQ7: 3555.01 | BR7: 4577.57 | BS7: 7143.89 | BT7: 5520.03 | BU7: 4786.4 | BV7: 8398.53 | BW7: 8073.17 | BX7: 8461.59 | BY7: 5388.81 | BZ7: 4779.79 | CA7: 6031.49 | CB7: 3373.73 | CC7: 4909.5 | CD7: 4465.33 | CE7: 6072.96 | CF7: 5354.67 | CG7: 5519.89 | CH7: 8782.27 | CI7: 8623.25 | CJ7: 6596.2 | CK7: 6330.6 | CL7: 7523.48 | CM7: 6280.96 | CN7: 4734.88 | CO7: 6733.53 | CP7: 6199.25 | CQ7: 6798.61 | CR7: 5976.81 | CS7: 7669.02 | CT7: 12354.09 | CU7: 12682.7 | CV7: 8438.88 | CW7: 9116.46 | CX7: 11531.07 | CY7: 6986.57 | CZ7: 5131.97 | DA7: 10669.69 | DB7: 8052.2 | DC7: 9029.33 | DD7: 12109.92 | DE7: 8089.85 | DF7: 9939.87 | DG7: 10914.69 | DH7: 8861.73 | DI7: 9960 | DJ7: 9384.86 | DK7: 6137.83 | DL7: 6187.88 | DM7: 7818.28 | DN7: 6611.52 | DO7: 7913.55 | DP7: 8575.51 | DQ7: 11836.04 | DR7: 12607.09 | DS7: 11907.04 | DT7: 13986.5 | DU7: 8608.43 | DV7: 6254.05 | DW7: 5355.97 | DX7: 7154.46 | DY7: 7973.91 | DZ7: 10508.4 | EA7: 7473.06 | EB7: 7216.09 | EC7: 8463.58 | ED7: 10767.58 | EE7: 11947.44 | EF7: 9420.27 | EG7: 8525.04 | EH7: 7066.07 | EI7: 5475.7 | EJ7: 4603.25 | EK7: 9810.21 | EL7: 10448.8 | EM7: 12785.51 | EN7: 10234.87 | EO7: 9764.52 | EP7: 6497.7 | EQ7: 8542.67 | ER7: 6765.72 | ES7: 5494.73 | ET7: 5469.26 | EU7: 4586.4 | EV7: 4386.34 | EW7: 2958.44 | EX7: 3341.07 | EY7: 3990.07 | EZ7: 4507.59 | FA7: 4933.32 | FB7: 7803.99 | FC7: 9844.94 | FD7: 8516.2 | FE7: 8507.72 | FF7: 8149.42 | FG7: 7118.31 | FH7: 559.73 | FI7: 416.9 | FJ7: 682.54 | FK7: 9183.48 | FL7: 9471.56 | FM7: 3199.79 | FR7: Addition
A8: Fruits Exports (MT) | N8: 1330.3 | O8: 2024.6 | P8: 4823.8 | Q8: 3973.4 | R8: 4298.8 | S8: 2337.4 | T8: 2197.6 | U8: 1919.3 | V8: 965.4 | W8: 910.1 | X8: 1036.9 | Y8: 1233.3 | Z8: 1551.4 | AA8: 2287.7 | AB8: 3528.6 | AC8: 2827.1 | AD8: 2480.1 | AE8: 3361.8 | AF8: 4838.5 | AG8: 3675.9 | AH8: 2381 | AI8: 1193.7 | AJ8: 1381.4 | AK8: 1562.9 | AL8: 1534.62 | AM8: 2367.21 | AN8: 3858.7 | AO8: 4780.72 | AP8: 2473.41 | AQ8: 2095.45 | AR8: 3049.39 | AS8: 2647.15 | AT8: 1712.31 | AU8: 2181.23 | AV8: 1922.28 | AW8: 2485 | AX8: 3037.65 | AY8: 3429.73 | AZ8: 2725.43 | BA8: 3482.85 | BB8: 3056.58 | BC8: 3347.01 | BD8: 3951.95 | BE8: 3417.67 | BF8: 2502.79 | BG8: 1992.42 | BH8: 2092.84 | BI8: 2112.29 | BJ8: 2714.41 | BK8: 2955.94 | BL8: 3468.87 | BM8: 3850.57 | BN8: 3667.32 | BO8: 4562.91 | BP8: 5614.13 | BQ8: 3782.35 | BR8: 7473.63 | BS8: 2406.24 | BT8: 2477.74 | BU8: 3272.23 | BV8: 3385.51 | BW8: 3807.98 | BX8: 6129.92 | BY8: 7865.7 | BZ8: 4748.73 | CA8: 4245.78 | CB8: 4274.02 | CC8: 4119.43 | CD8: 2278.11 | CE8: 2297.36 | CF8: 2417.37 | CG8: 3087.92 | CH8: 5870.92 | CI8: 4922.09 | CJ8: 6151.45 | CK8: 6361.8 | CL8: 7180.31 | CM8: 6821.85 | CN8: 5475.41 | CO8: 3908.37 | CP8: 3441.02 | CQ8: 1815.36 | CR8: 2301.27 | CS8: 2695.52 | CT8: 2897.01 | CU8: 5973.81 | CV8: 10758.95 | CW8: 11995.51 | CX8: 7535.17 | CY8: 6948.9 | CZ8: 7020.27 | DA8: 8403.1 | DB8: 5989.53 | DC8: 2235.8 | DD8: 2577.43 | DE8: 3306.5 | DF8: 3241.48 | DG8: 8564.62 | DH8: 12183.15 | DI8: 10403.68 | DJ8: 8915.77 | DK8: 7038.09 | DL8: 8546.38 | DM8: 6409.13 | DN8: 4039.75 | DO8: 4684.22 | DP8: 4122.71 | DQ8: 3733.84 | DR8: 6340.04 | DS8: 8370.27 | DT8: 11433.3 | DU8: 11671.61 | DV8: 13492.51 | DW8: 10367.69 | DX8: 9990.93 | DY8: 8874.5 | DZ8: 6250.47 | EA8: 7073.45 | EB8: 5607.97 | EC8: 5586.8 | ED8: 7071.82 | EE8: 11738.47 | EF8: 19399.89 | EG8: 19046.36 | EH8: 13433.19 | EI8: 11415.49 | EJ8: 5116.9 | EK8: 8742.79 | EL8: 6260.5 | EM8: 5105.03 | EN8: 3157.16 | EO8: 6834.19 | EP8: 5631.1 | EQ8: 2083.84 | ER8: 7495.87 | ES8: 8372.43 | ET8: 9584.9 | EU8: 10905.97 | EV8: 14352.89 | EW8: 11042.71 | EX8: 6992.45 | EY8: 5775.82 | EZ8: 5394.69 | FA8: 4949.13 | FB8: 13539.46 | FC8: 7357.47 | FD8: 16696.8 | FE8: 25735.04 | FF8: 21865.24 | FG8: 21229.39 | FH8: 25130.29 | FI8: 26484.04 | FJ8: 14886.92 | FK8: 10002.6 | FL8: 3474.92 | FM8: 1699.5 | FR8: Addition
A9: Fruits Exports (Ksh Million) | N9: 191.8 | O9: 351 | P9: 539.3 | Q9: 436.3 | R9: 412.3 | S9: 288.1 | T9: 308.6 | U9: 308.7 | V9: 157.2 | W9: 194.5 | X9: 168.5 | Y9: 179.3 | Z9: 196.1 | AA9: 241.7 | AB9: 325.9 | AC9: 294.9 | AD9: 343.4 | AE9: 502.9 | AF9: 716.3 | AG9: 807.6 | AH9: 397.1 | AI9: 317.2 | AJ9: 253.5 | AK9: 283.2 | AL9: 229.46 | AM9: 293.1 | AN9: 406.09 | AO9: 483.41 | AP9: 340.1 | AQ9: 380.97 | AR9: 446.62 | AS9: 398.67 | AT9: 219.85 | AU9: 445.13 | AV9: 403.15 | AW9: 435.97 | AX9: 435.92 | AY9: 403.92 | AZ9: 377.43 | BA9: 574.13 | BB9: 324.41 | BC9: 441.47 | BD9: 581.32 | BE9: 576.84 | BF9: 654.75 | BG9: 418.84 | BH9: 317.29 | BI9: 304.32 | BJ9: 476.82 | BK9: 412.23 | BL9: 496.71 | BM9: 548.16 | BN9: 436.24 | BO9: 557.52 | BP9: 882.68 | BQ9: 613.49 | BR9: 623.85 | BS9: 477.01 | BT9: 445.38 | BU9: 591.71 | BV9: 605.03 | BW9: 561.37 | BX9: 852.27 | BY9: 1073.93 | BZ9: 643.76 | CA9: 562.91 | CB9: 675.38 | CC9: 776.39 | CD9: 377.65 | CE9: 365.15 | CF9: 377.66 | CG9: 445.76 | CH9: 819.86 | CI9: 678.67 | CJ9: 853.46 | CK9: 832.96 | CL9: 954.86 | CM9: 1187.28 | CN9: 1066.66 | CO9: 786.16 | CP9: 649.33 | CQ9: 316.44 | CR9: 374.8 | CS9: 488.84 | CT9: 458.01 | CU9: 827.86 | CV9: 2079.12 | CW9: 1627.26 | CX9: 1076.26 | CY9: 1241.66 | CZ9: 1213.97 | DA9: 1608.97 | DB9: 1268.93 | DC9: 393.45 | DD9: 465.46 | DE9: 570.14 | DF9: 507.45 | DG9: 1236.09 | DH9: 1757.85 | DI9: 1542.81 | DJ9: 1152.12 | DK9: 1201.85 | DL9: 1556.23 | DM9: 1158.65 | DN9: 522.83 | DO9: 913.66 | DP9: 810.09 | DQ9: 829.42 | DR9: 1076 | DS9: 1044.26 | DT9: 1683.33 | DU9: 1640.06 | DV9: 5642.88 | DW9: 1431.74 | DX9: 1424.36 | DY9: 1286.9 | DZ9: 990.26 | EA9: 889.94 | EB9: 646.27 | EC9: 670.96 | ED9: 1038.19 | EE9: 1697.31 | EF9: 2893.9 | EG9: 2719.63 | EH9: 1927.87 | EI9: 1804.96 | EJ9: 919.67 | EK9: 1614.25 | EL9: 1346.72 | EM9: 745.01 | EN9: 870.38 | EO9: 805.01 | EP9: 762.1 | EQ9: 291.81 | ER9: 954.8 | ES9: 1119.08 | ET9: 1162.11 | EU9: 1343.36 | EV9: 1758.37 | EW9: 1521.69 | EX9: 1094.93 | EY9: 953.49 | EZ9: 722.35 | FA9: 664.1 | FB9: 2204.99 | FC9: 1045.46 | FD9: 2835.59 | FE9: 4315.05 | FF9: 3766.27 | FG9: 3575.54 | FH9: 4426.65 | FI9: 4959.62 | FJ9: 2559.2 | FK9: 1869.63 | FL9: 566.27 | FM9: 248.89 | FR9: Addition
A10: Vegetables Exports (MT) | N10: 6293.5 | O10: 5990.4 | P10: 6854.5 | Q10: 7732.4 | R10: 7473.9 | S10: 6987.6 | T10: 5234.2 | U10: 6210.3 | V10: 6588.6 | W10: 7016.5 | X10: 6706.8 | Y10: 6157 | Z10: 4297 | AA10: 3638.9 | AB10: 5260.6 | AC10: 5488.1 | AD10: 5346 | AE10: 4851 | AF10: 5212.3 | AG10: 4421 | AH10: 5675.8 | AI10: 8266.4 | AJ10: 6854.6 | AK10: 7040.4 | AL10: 7377.74 | AM10: 8099.7 | AN10: 5344.51 | AO10: 6363.77 | AP10: 5190.76 | AQ10: 6232.14 | AR10: 5113.57 | AS10: 5766.1 | AT10: 7512.3 | AU10: 8090.7 | AV10: 6662.14 | AW10: 5418.88 | AX10: 6471.3 | AY10: 4696.2 | AZ10: 5438.82 | BA10: 6263.91 | BB10: 6032.04 | BC10: 5832.06 | BD10: 4846.55 | BE10: 5432.45 | BF10: 6337.67 | BG10: 8202.14 | BH10: 5380.74 | BI10: 5400.66 | BJ10: 5109.74 | BK10: 4992.44 | BL10: 5959.02 | BM10: 6686 | BN10: 4644.36 | BO10: 4693.06 | BP10: 3787.02 | BQ10: 4191.62 | BR10: 7176.76 | BS10: 8395.18 | BT10: 6731.88 | BU10: 6575.33 | BV10: 6758.37 | BW10: 4811.68 | BX10: 5804.76 | BY10: 5744.89 | BZ10: 4870.06 | CA10: 7007.28 | CB10: 5785.96 | CC10: 6245.95 | CD10: 8040.14 | CE10: 8486.92 | CF10: 8256.31 | CG10: 6978.28 | CH10: 8326.11 | CI10: 6962.03 | CJ10: 7345.77 | CK10: 5675.43 | CL10: 7274.99 | CM10: 7203.98 | CN10: 6539.94 | CO10: 7713.89 | CP10: 7648.91 | CQ10: 7953.25 | CR10: 7152.79 | CS10: 7443.18 | CT10: 8293.18 | CU10: 6128.07 | CV10: 7548.81 | CW10: 4825.37 | CX10: 6792.62 | CY10: 4946.37 | CZ10: 4421.85 | DA10: 7090.14 | DB10: 10148.38 | DC10: 10841.18 | DD10: 8819.18 | DE10: 5963.54 | DF10: 9794.17 | DG10: 7016.72 | DH10: 5357.63 | DI10: 5149.66 | DJ10: 5275.12 | DK10: 5770.09 | DL10: 5218.74 | DM10: 5312.26 | DN10: 5061.47 | DO10: 6003.68 | DP10: 6500.21 | DQ10: 6273.72 | DR10: 4834.01 | DS10: 4809.2 | DT10: 5585.21 | DU10: 4839.67 | DV10: 4281.66 | DW10: 4678.09 | DX10: 4547 | DY10: 4561.09 | DZ10: 5405 | EA10: 6274.31 | EB10: 5551.46 | EC10: 7208.7 | ED10: 6066.26 | EE10: 5363.26 | EF10: 7053.12 | EG10: 6177.43 | EH10: 6694.81 | EI10: 8942.62 | EJ10: 3522.29 | EK10: 7206.65 | EL10: 7956.41 | EM10: 8435.29 | EN10: 4001.6 | EO10: 6643.5 | EP10: 2355.98 | EQ10: 2687.27 | ER10: 6746.42 | ES10: 5199.03 | ET10: 4411.57 | EU10: 5016.12 | EV10: 3386.96 | EW10: 6022.55 | EX10: 5671.93 | EY10: 6821.14 | EZ10: 6239.38 | FA10: 6935.02 | FB10: 13133.25 | FC10: 9339.6 | FD10: 9955.59 | FE10: 9040.69 | FF10: 13365.22 | FG10: 13975.13 | FH10: 12954.37 | FI10: 18562.68 | FJ10: 24607.34 | FK10: 19752.72 | FL10: 14599.76 | FM10: 4777.58 | FR10: Addition
A11: Vegetables Exports (Ksh Million) | N11: 2384.3 | O11: 1798.9 | P11: 2539.9 | Q11: 2260.2 | R11: 2961.6 | S11: 2689.2 | T11: 1740.2 | U11: 1975.6 | V11: 1800.4 | W11: 2110.4 | X11: 2095.6 | Y11: 1894.7 | Z11: 1298.5 | AA11: 1136.7 | AB11: 1516.3 | AC11: 1813.8 | AD11: 1413.3 | AE11: 2151.6 | AF11: 1759.8 | AG11: 1348.1 | AH11: 1580.8 | AI11: 2057.7 | AJ11: 1967.3 | AK11: 2181.6 | AL11: 2074.65 | AM11: 1630.39 | AN11: 1824.87 | AO11: 1669.46 | AP11: 1476.29 | AQ11: 2329.81 | AR11: 1440.68 | AS11: 1820.18 | AT11: 1798.5 | AU11: 2604.61 | AV11: 2559.4 | AW11: 1694.47 | AX11: 1845.56 | AY11: 1262.87 | AZ11: 1479.17 | BA11: 1618.92 | BB11: 1648.08 | BC11: 1546.46 | BD11: 1508.39 | BE11: 1756.11 | BF11: 1455.92 | BG11: 1531.95 | BH11: 1554.31 | BI11: 1572.89 | BJ11: 1556.47 | BK11: 1362.6 | BL11: 1498.63 | BM11: 1371.45 | BN11: 1431.59 | BO11: 1337.88 | BP11: 1305.19 | BQ11: 1655.3 | BR11: 2985.9 | BS11: 2283.57 | BT11: 2129.59 | BU11: 2021.33 | BV11: 1923.64 | BW11: 1516.29 | BX11: 1825.83 | BY11: 2147.97 | BZ11: 1580.73 | CA11: 3698.28 | CB11: 1527.75 | CC11: 1607.08 | CD11: 1815.98 | CE11: 1873.98 | CF11: 1909.08 | CG11: 1940.17 | CH11: 1956.81 | CI11: 1639.72 | CJ11: 1644.29 | CK11: 1813.27 | CL11: 1814.03 | CM11: 1927.01 | CN11: 2858.39 | CO11: 1717.46 | CP11: 2113.84 | CQ11: 1944 | CR11: 1923.05 | CS11: 2712.78 | CT11: 2086.58 | CU11: 2946.02 | CV11: 2098.62 | CW11: 2130.99 | CX11: 1949.64 | CY11: 1410.29 | CZ11: 1387.96 | DA11: 2842.46 | DB11: 2535.59 | DC11: 2617.76 | DD11: 2426.02 | DE11: 3253.25 | DF11: 2503.41 | DG11: 1869.56 | DH11: 1826.03 | DI11: 2171.14 | DJ11: 1810.5 | DK11: 3746.19 | DL11: 1736.8 | DM11: 2173.38 | DN11: 2602.52 | DO11: 1996.43 | DP11: 2444.94 | DQ11: 2366.88 | DR11: 2355.84 | DS11: 1983.4 | DT11: 2338.23 | DU11: 1664.25 | DV11: 2176.03 | DW11: 1741.78 | DX11: 1819.98 | DY11: 1708.51 | DZ11: 1910.75 | EA11: 2169.66 | EB11: 1929.8 | EC11: 2430.21 | ED11: 3430.9 | EE11: 2222.24 | EF11: 2697.68 | EG11: 2253.52 | EH11: 2472.27 | EI11: 2447.22 | EJ11: 1297.88 | EK11: 2664.92 | EL11: 2601.13 | EM11: 2608.88 | EN11: 2085.64 | EO11: 1678.4 | EP11: 867.14 | EQ11: 228.12 | ER11: 1109.34 | ES11: 1062.32 | ET11: 1121.2 | EU11: 1038.09 | EV11: 1294.81 | EW11: 1316.61 | EX11: 1232.3 | EY11: 1428.05 | EZ11: 1763.46 | FA11: 2121.68 | FB11: 3186.02 | FC11: 2347.31 | FD11: 2734.92 | FE11: 3010.64 | FF11: 4318.57 | FG11: 3987.78 | FH11: 3890.62 | FI11: 5020.34 | FJ11: 5903.31 | FK11: 7647.58 | FL11: 7456.62 | FM11: 1362.95 | FR11: Addition
A12: Coffee Exports (MT) | V12: 3317 | W12: 3298 | X12: 1989.9 | Y12: 1672 | Z12: 3093.7 | AA12: 3668 | AB12: 5068.9 | AC12: 4624.5 | AD12: 4923.9 | AE12: 4887.2 | AF12: 5727.3 | AG12: 4483.8 | AH12: 4421 | AI12: 4481.5 | AJ12: 4109.6 | AK12: 2223.2 | AL12: 3093.7 | AM12: 3668 | AN12: 5068.9 | AO12: 3986.1 | AP12: 5163.8 | AQ12: 5237.7 | AR12: 4652.1 | AS12: 4740.8 | AT12: 4802.3 | AU12: 3899.2 | AV12: 3808.2 | AW12: 2675 | AX12: 3168.9 | AY12: 3077.9 | AZ12: 4583.6 | BA12: 4858.3 | BB12: 4593.6 | BC12: 4587.4 | BD12: 5424.5 | BE12: 3313.1 | BF12: 3944.1 | BG12: 3617.7 | BH12: 3717.9 | BI12: 2550.9 | BJ12: 2843.8 | BK12: 2883.6 | BL12: 4289.5 | BM12: 3948.3 | BN12: 4382.8 | BO12: 4219.9 | BP12: 3938.3 | BQ12: 3991.1 | BR12: 3404.9 | BS12: 4399.9 | BT12: 2769.3 | BU12: 2528.1 | BV12: 2448.81 | BW12: 3276.64 | BX12: 4168.55 | BY12: 4803.85 | BZ12: 4814.01 | CA12: 4982.7 | CB12: 3986.91 | CC12: 3718.69 | CD12: 3172.75 | CE12: 3116.14 | CF12: 3928.6 | CG12: 2885.77 | CH12: 3213.6 | CI12: 3868.37 | CJ12: 5447.43 | CK12: 4200.84 | CL12: 5423.67 | CM12: 4442.89 | CN12: 3597.63 | CO12: 2648.78 | CP12: 3133.57 | CQ12: 2335.03 | CR12: 3195.62 | CS12: 1955.49 | CT12: 2509.26 | CU12: 2834.28 | CV12: 3936.1 | CW12: 4550.24 | CX12: 5572.91 | CY12: 4649.03 | CZ12: 4683.09 | DA12: 2972.69 | DB12: 2519.53 | DC12: 3521.39 | DD12: 4619.48 | DE12: 2311.6 | DF12: 3469.39 | DG12: 4567.37 | DH12: 4351.34 | DI12: 4551.54 | DJ12: 5489.9 | DK12: 4548.7 | DL12: 5115.45 | DM12: 3931.89 | DN12: 3144.73 | DO12: 3985.76 | DP12: 3664.41 | DQ12: 1905.94 | DR12: 2639.38 | DS12: 3168.5 | DT12: 4604.42 | DU12: 4395.52 | DV12: 4312.75 | DW12: 5414.08 | DX12: 3546.25 | DY12: 3181.82 | DZ12: 3391.49 | EA12: 2732.15 | EB12: 3594.29 | EC12: 2405.44 | ED12: 2129.36 | EE12: 3481.13 | EF12: 6065.07 | EG12: 3337.01 | EH12: 4430.33 | EI12: 3436.88 | EJ12: 2696.29 | EK12: 2504.38 | EL12: 2480.29 | EM12: 2432.2 | EN12: 2170.19 | EO12: 2314.35 | EP12: 3238.6 | EQ12: 4617.63 | ER12: 4066.91 | ES12: 5749.32 | ET12: 5902.59 | EU12: 4945.48 | EV12: 5179.34 | EW12: 3212.76 | EX12: 3172.29 | EY12: 3223.81 | EZ12: 3653.89 | FA12: 2223.8 | FB12: 1921.19 | FC12: 3877.74 | FD12: 5486 | FE12: 5428.04 | FF12: 6359.29 | FG12: 7078.27 | FH12: 6174.9 | FI12: 4652.03 | FJ12: 2967.04 | FK12: 1704.74 | FL12: 1694.58 | FM12: 1478.34 | FN12: 2685.8 | FO12: 2745.22 | FP12: 4291.32 | FR12: Addition
A13: Coffee Export (Ksh Million) | V13: 2161.4 | W13: 2133.5 | X13: 1173 | Y13: 940.4 | Z13: 1453.7 | AA13: 1937.4 | AB13: 2550.4 | AC13: 2368.7 | AD13: 2274.6 | AE13: 2098.2 | AF13: 2396.9 | AG13: 1712 | AH13: 1596.2 | AI13: 1689.7 | AJ13: 1453.1 | AK13: 740.4 | AL13: 1453.7 | AM13: 1937.4 | AN13: 2550.4 | AO13: 1361.5 | AP13: 1789.8 | AQ13: 1778.3 | AR13: 1555.8 | AS13: 1409 | AT13: 1436.1 | AU13: 1302.9 | AV13: 1153.1 | AW13: 862.3 | AX13: 1054.8 | AY13: 1117.6 | AZ13: 1533.2 | BA13: 2013.3 | BB13: 2024.2 | BC13: 2006.8 | BD13: 2383.4 | BE13: 1473.6 | BF13: 1722 | BG13: 1645.1 | BH13: 1747 | BI13: 1192.3 | BJ13: 1306.5 | BK13: 1338.5 | BL13: 2025.1 | BM13: 1900.5 | BN13: 2235.8 | BO13: 2068.1 | BP13: 1943 | BQ13: 1790.3 | BR13: 1617.4 | BS13: 2019.1 | BT13: 1243.5 | BU13: 1092 | BV13: 1184.3 | BW13: 1636.25 | BX13: 2206.07 | BY13: 2540.37 | BZ13: 2170.48 | CA13: 2369.1 | CB13: 1797.66 | CC13: 1636.87 | CD13: 1398.5 | CE13: 1489.24 | CF13: 1690.64 | CG13: 1251.95 | CH13: 1552.64 | CI13: 2093.59 | CJ13: 3231.4 | CK13: 2697.57 | CL13: 3116.68 | CM13: 2500.75 | CN13: 1971.05 | CO13: 1311.27 | CP13: 1516.1 | CQ13: 1121.21 | CR13: 1565.89 | CS13: 774.53 | CT13: 1285.98 | CU13: 1612.42 | CV13: 2236.94 | CW13: 2822.2 | CX13: 3209.36 | CY13: 2664.46 | CZ13: 2457.05 | DA13: 1546.91 | DB13: 1141.39 | DC13: 1467.33 | DD13: 1729.5 | DE13: 921.35 | DF13: 1498.72 | DG13: 1903.18 | DH13: 2256.18 | DI13: 2500.94 | DJ13: 2699.81 | DK13: 1963.94 | DL13: 1713.18 | DM13: 1461.51 | DN13: 1112.65 | DO13: 1390.06 | DP13: 1175.66 | DQ13: 633.74 | DR13: 985.32 | DS13: 1686.82 | DT13: 2410.16 | DU13: 2590.2 | DV13: 2279.12 | DW13: 2956.33 | DX13: 1799.26 | DY13: 1484.15 | DZ13: 1606.84 | EA13: 1322.08 | EB13: 1836.61 | EC13: 1284.84 | ED13: 1342.45 | EE13: 2161.12 | EF13: 4556.94 | EG13: 2307.12 | EH13: 3010.49 | EI13: 2271.77 | EJ13: 1763.9 | EK13: 1657.82 | EL13: 1735.13 | EM13: 1674.37 | EN13: 1740.12 | EO13: 1918.64 | EP13: 2633.51 | EQ13: 3546.19 | ER13: 3415.52 | ES13: 4467.98 | ET13: 4876.67 | EU13: 3818.23 | EV13: 3824.46 | EW13: 2482.09 | EX13: 2364.86 | EY13: 2412.46 | EZ13: 2387.92 | FA13: 1415.65 | FB13: 1217.32 | FC13: 2569.47 | FD13: 3850.91 | FE13: 3895.82 | FF13: 4744.53 | FG13: 5000.89 | FH13: 4191.84 | FI13: 3263.78 | FJ13: 2023.86 | FK13: 1268.72 | FL13: 1357.99 | FM13: 1225.7 | FN13: 2112.12 | FO13: 2134.13 | FP13: 3349.81 | FR13: Addition
A14: Tea Export (MT) | V14: 26429.7 | W14: 29421.7 | X14: 33352.5 | Y14: 35186.6 | Z14: 35381.6 | AA14: 37656.2 | AB14: 31280.3 | AC14: 26816.3 | AD14: 25060.1 | AE14: 29147.6 | AF14: 28054.4 | AG14: 30996.2 | AH14: 30688.6 | AI14: 33166.5 | AJ14: 38681 | AK14: 30067.4 | AL14: 35381.6 | AM14: 37656.2 | AN14: 31280.3 | AO14: 33661.5 | AP14: 40935.5 | AQ14: 37782.7 | AR14: 43760.8 | AS14: 36175.1 | AT14: 34082.3 | AU14: 33531.7 | AV14: 40054.4 | AW14: 38740.7 | AX14: 38651.9 | AY14: 33514.1 | AZ14: 37642.4 | BA14: 37439 | BB14: 36215.5 | BC14: 39010.7 | BD14: 42393.4 | BE14: 38120.5 | BF14: 35960.6 | BG14: 37637.2 | BH14: 38275.2 | BI14: 41631.3 | BJ14: 40970.1 | BK14: 41086.2 | BL14: 35699.6 | BM14: 28262.1 | BN14: 27016.3 | BO14: 35914.8 | BP14: 30623 | BQ14: 27687.5 | BR14: 33528.1 | BS14: 40246.1 | BT14: 36714.2 | BU14: 42779.4 | BV14: 36574.84 | BW14: 43292.1 | BX14: 37571.21 | BY14: 39312.62 | BZ14: 44901.21 | CA14: 52175.28 | CB14: 42751.15 | CC14: 39672.66 | CD14: 33528.46 | CE14: 29655.58 | CF14: 41138.04 | CG14: 39396.12 | CH14: 46434.4 | CI14: 33897.69 | CJ14: 33662.22 | CK14: 32091.19 | CL14: 39328.77 | CM14: 42369.54 | CN14: 41437.02 | CO14: 29628.45 | CP14: 43469.19 | CQ14: 41172.86 | CR14: 39127.97 | CS14: 44412.57 | CT14: 48446.76 | CU14: 47356.65 | CV14: 34487.7 | CW14: 33564.66 | CX14: 42532.98 | CY14: 45182.21 | CZ14: 45242.32 | DA14: 38022.53 | DB14: 40267.54 | DC14: 43893.85 | DD14: 44107.54 | DE14: 38680.96 | DF14: 48622.81 | DG14: 41026.62 | DH14: 42457.17 | DI14: 36883.92 | DJ14: 36993.68 | DK14: 29355.17 | DL14: 33657.14 | DM14: 41275.96 | DN14: 36325.07 | DO14: 45373.9 | DP14: 43650.47 | DQ14: 39312.4 | DR14: 48770.49 | DS14: 47569.72 | DT14: 51440.71 | DU14: 57722.34 | DV14: 48594.07 | DW14: 46399.01 | DX14: 46850.57 | DY14: 47034.93 | DZ14: 44724.7 | EA14: 43655.91 | EB14: 46352.88 | EC14: 46166.69 | ED14: 48811.79 | EE14: 50389.92 | EF14: 53432.1 | EG14: 51899.23 | EH14: 50041.59 | EI14: 43993.25 | EJ14: 43844.48 | EK14: 44421.07 | EL14: 36307.66 | EM14: 40078.09 | EN14: 45318.19 | EO14: 47922.07 | EP14: 45584.65 | EQ14: 44093.16 | ER14: 46043.56 | ES14: 43446.02 | ET14: 47380.14 | EU14: 46794.67 | EV14: 45583.93 | EW14: 42940.45 | EX14: 48312.32 | EY14: 41077.4 | EZ14: 51640.54 | FA14: 47847.99 | FB14: 44556.08 | FC14: 44328.68 | FD14: 50831.02 | FE14: 37025.13 | FF14: 48229.28 | FG14: 45317.56 | FH14: 39943.62 | FI14: 58590.66 | FJ14: 47806.68 | FK14: 45359.87 | FL14: 49507.33 | FM14: 46524.9 | FN14: 51187.58 | FO14: 59043.65 | FP14: 59599.15 | FR14: Addition
A15: Tea Export (Ksh Million) | V15: 7686.4 | W15: 8855.3 | X15: 9333.6 | Y15: 9145.1 | Z15: 9122.8 | AA15: 9414.5 | AB15: 7804.2 | AC15: 6751.1 | AD15: 6445.2 | AE15: 7770.2 | AF15: 7812.6 | AG15: 8798 | AH15: 8771.3 | AI15: 9447.5 | AJ15: 10840.4 | AK15: 8462.9 | AL15: 9122.8 | AM15: 9414.5 | AN15: 7804.2 | AO15: 8011.9 | AP15: 9462.9 | AQ15: 8515.1 | AR15: 9911 | AS15: 8236.4 | AT15: 7635.4 | AU15: 6977 | AV15: 7834.3 | AW15: 7991.4 | AX15: 8784.3 | AY15: 7316.6 | AZ15: 7937.6 | BA15: 7781.7 | BB15: 7380 | BC15: 7692.3 | BD15: 8468 | BE15: 7974.2 | BF15: 7243.6 | BG15: 7444.3 | BH15: 7594.6 | BI15: 8378.6 | BJ15: 8484.7 | BK15: 9313.4 | BL15: 8796.1 | BM15: 7189.1 | BN15: 7505.7 | BO15: 11262.8 | BP15: 10146.4 | BQ15: 9481 | BR15: 11412.8 | BS15: 13538.3 | BT15: 12126 | BU15: 13768.2 | BV15: 11013.11 | BW15: 12200.37 | BX15: 9886.75 | BY15: 9516.83 | BZ15: 10657.68 | CA15: 12613.19 | CB15: 10679.32 | CC15: 9993.36 | CD15: 8453.73 | CE15: 7547.5 | CF15: 11123.43 | CG15: 10811.39 | CH15: 14072.07 | CI15: 10879.8 | CJ15: 10693.17 | CK15: 9991.02 | CL15: 12354.06 | CM15: 13485.25 | CN15: 13442.3 | CO15: 9268.76 | CP15: 13569.85 | CQ15: 13147.28 | CR15: 12712.92 | CS15: 13634.34 | CT15: 14964.45 | CU15: 14656.94 | CV15: 10470.94 | CW15: 9829.58 | CX15: 11703.03 | CY15: 12463.24 | CZ15: 12226.12 | DA15: 9919.47 | DB15: 10478.62 | DC15: 11327.26 | DD15: 11014.55 | DE15: 9781.31 | DF15: 11831.3 | DG15: 9638.24 | DH15: 9910.41 | DI15: 8630.54 | DJ15: 9292.8 | DK15: 7154.11 | DL15: 7788.4 | DM15: 9458.09 | DN15: 8462.91 | DO15: 11064.77 | DP15: 10735.39 | DQ15: 9483.99 | DR15: 11452.01 | DS15: 11021.86 | DT15: 11665.48 | DU15: 13192.62 | DV15: 11289.33 | DW15: 10293 | DX15: 10013.82 | DY15: 10269.11 | DZ15: 10199.89 | EA15: 9937.34 | EB15: 10610.96 | EC15: 10300.58 | ED15: 11378.64 | EE15: 11725.86 | EF15: 12672.9 | EG15: 11575.75 | EH15: 11070.79 | EI15: 9547.74 | EJ15: 9203.5 | EK15: 9874.4 | EL15: 8565.59 | EM15: 10316.47 | EN15: 12180.56 | EO15: 12724.88 | EP15: 12628.76 | EQ15: 13303.4 | ER15: 13558.64 | ES15: 12769.02 | ET15: 13776.91 | EU15: 13693.39 | EV15: 13464.54 | EW15: 12603.59 | EX15: 14167.67 | EY15: 12252.62 | EZ15: 16035.25 | FA15: 14892.05 | FB15: 13519.65 | FC15: 13510.62 | FD15: 16190.79 | FE15: 12179.71 | FF15: 16176.45 | FG15: 15446.15 | FH15: 12910.37 | FI15: 20193.05 | FJ15: 16980.13 | FK15: 16111.63 | FL15: 17767.98 | FM15: 17283.71 | FN15: 18267.6 | FO15: 20429.82 | FP15: 19070.04 | FR15: Addition
A16: Cane Deliveries ('000 Metric Tonnes) | AX16: 693.47 | AY16: 620.51 | AZ16: 645.88 | BA16: 543.85 | BB16: 533.67 | BC16: 523.75 | BD16: 593.2 | BE16: 547.65 | BF16: 533.43 | BG16: 467.11 | BH16: 369.34 | BI16: 405.79 | BJ16: 676.67 | BK16: 596.04 | BL16: 675.09 | BM16: 558.33 | BN16: 542.06 | BO16: 560.96 | BP16: 558.9 | BQ16: 598.42 | BR16: 673.15 | BS16: 636.23 | BT16: 513.82 | BU16: 575.13 | BV16: 670.46 | BW16: 640.51 | BX16: 757.06 | BY16: 576.69 | BZ16: 514.66 | CA16: 630.06 | CB16: 609.77 | CC16: 564.7 | CD16: 566.99 | CE16: 576.53 | CF16: 506.42 | CG16: 537.81 | CH16: 581.6 | CI16: 519.4 | CJ16: 470.73 | CK16: 304.79 | CL16: 231.97 | CM16: 243.81 | CN16: 246.89 | CO16: 176.33 | CP16: 351.75 | CQ16: 407.06 | CR16: 578.31 | CS16: 638.97 | CT16: 687.52 | CU16: 555.88 | CV16: 445.17 | CW16: 324.41 | CX16: 266.43 | CY16: 314.13 | CZ16: 378.6 | DA16: 438.73 | DB16: 445.69 | DC16: 492.95 | DD16: 491.96 | DE16: 420.7 | DF16: 538.67 | DG16: 453.48 | DH16: 456.17 | DI16: 381.71 | DJ16: 348.04 | DK16: 259.27 | DL16: 266.97 | DM16: 357.56 | DN16: 397.52 | DO16: 406.53 | DP16: 357.45 | DQ16: 381.74 | DR16: 522.89 | DS16: 529.94 | DT16: 583.14 | DU16: 534.69 | DV16: 544.36 | DW16: 572.37 | DX16: 625.61 | DY16: 629.1 | DZ16: 645.31 | EA16: 644.24 | EB16: 594.18 | EC16: 468.59 | ED16: 681.54 | EE16: 660.44 | EF16: 709.46 | EG16: 631.43 | EH16: 636.46 | EI16: 639.35 | EJ16: 636.55 | EK16: 679.56 | EL16: 517.93 | EM16: 551.68 | EN16: 663.71 | EO16: 649.4 | EP16: 691.11 | EQ16: 664.01 | ER16: 825.18 | ES16: 719.48 | ET16: 673.2 | EU16: 763.3 | EV16: 751.84 | EW16: 512.85 | EX16: 680 | EY16: 824.14 | EZ16: 779.61 | FA16: 700.7 | FB16: 908.58 | FC16: 716.27 | FD16: 546.15 | FE16: 405.39 | FF16: 408.19 | FG16: 436.69 | FH16: 395.23 | FI16: 295.81 | FJ16: 182.97 | FK16: 282.08 | FL16: 296.17 | FM16: 610.02 | FN16: 713.51 | FO16: 756 | FP16: 834.88 | FR16: Addition
A17: Average Monthly Retail Prices for Dry Maize (per Kg) | DF17: 31.54 | DG17: 30.59 | DH17: 31.89 | DI17: 38.69 | DJ17: 42.71 | DK17: 43.91 | DL17: 46.45 | DM17: 42.14 | DN17: 41.49 | DO17: 43.94 | DP17: 45.93 | DQ17: 44.75 | DR17: 44.8 | DS17: 44.6 | DT17: 43.6 | DU17: 43.5 | DV17: 44.6 | DW17: 44.3 | DX17: 44.5 | DY17: 42.1 | DZ17: 41.4 | EA17: 39.4 | EB17: 40.5 | EC17: 40.4 | ED17: 37.3 | EE17: 37.4 | EF17: 37.8 | EG17: 37.9 | EH17: 37.9 | EI17: 40 | EJ17: 39.4 | EK17: 39 | EL17: 39.3 | EM17: 40.7 | EN17: 44.4 | EO17: 49.1 | EP17: 46.4 | EQ17: 45.6 | ER17: 47 | ES17: 51.4 | ET17: 58.2 | EU17: 70.3 | EV17: 77.3 | EW17: 77.6 | EX17: 76.1 | EY17: 77.9 | EZ17: 79.9 | FA17: 80.5 | FB17: 75.2 | FC17: 74.7 | FD17: 79.3 | FE17: 81.6 | FF17: 84.1 | FG17: 86.7 | FH17: 85.1 | FI17: 76.1 | FJ17: 71.9 | FK17: 70.7 | FL17: 69.2 | FM17: 70.2 | FN17: 65.9 | FO17: 61.6 | FP17: 57 | FR17: Average
A18: Average Monthly Retail Prices for Dry Beans (per Kg) | DF18: 77.99 | DG18: 75.04 | DH18: 77.01 | DI18: 83.05 | DJ18: 89.62 | DK18: 92.3 | DL18: 89.26 | DM18: 85.71 | DN18: 81.57 | DO18: 86.12 | DP18: 89.88 | DQ18: 89.54 | DR18: 89.1 | DS18: 91.8 | DT18: 96.2 | DU18: 104.6 | DV18: 104.7 | DW18: 103.3 | DX18: 99.2 | DY18: 95.8 | DZ18: 96.6 | EA18: 99.4 | EB18: 99.9 | EC18: 100.6 | ED18: 100.5 | EE18: 101.1 | EF18: 102.5 | EG18: 102 | EH18: 102.5 | EI18: 101.3 | EJ18: 100.5 | EK18: 99.6 | EL18: 104.3 | EM18: 102.6 | EN18: 103.4 | EO18: 102.4 | EP18: 104.1 | EQ18: 98.4 | ER18: 101.5 | ES18: 106.3 | ET18: 109.8 | EU18: 116.5 | EV18: 124 | EW18: 127.4 | EX18: 129.7 | EY18: 141.8 | EZ18: 147.3 | FA18: 147.3 | FB18: 146.4 | FC18: 149.7 | FD18: 165.2 | FE18: 177.8 | FF18: 185.5 | FG18: 181.6 | FH18: 174.9 | FI18: 172 | FJ18: 173 | FK18: 172.2 | FL18: 175.1 | FM18: 170.3 | FN18: 162.8 | FO18: 159.6 | FP18: 156.8 | FR18: Average
A19: Manufacturing, Building and Construction
A20: Sugar Production (MT) | B20: 48100 | C20: 42982 | D20: 45388 | E20: 43801 | F20: 34465 | G20: 37828 | H20: 33495 | I20: 41911 | J20: 45595 | K20: 43669 | L20: 50822 | M20: 55414 | N20: 55974 | O20: 52069 | P20: 53842 | Q20: 52061 | R20: 49130 | S20: 38818 | T20: 25884 | U20: 26060 | V20: 22815 | W20: 28990 | X20: 32689 | Y20: 36729 | Z20: 53852 | AA20: 49480 | AB20: 52342 | AC20: 44914 | AD20: 40410 | AE20: 45111 | AF20: 41607 | AG20: 37058 | AH20: 32503 | AI20: 30123 | AJ20: 31886 | AK20: 34651 | AL20: 49046 | AM20: 50036 | AN20: 43647 | AO20: 39151 | AP20: 36529 | AQ20: 49512 | AR20: 61802 | AS20: 58687 | AT20: 50303 | AU20: 52751 | AV20: 54752 | AW20: 53994 | AX20: 64298 | AY20: 60044 | AZ20: 63365 | BA20: 47279 | BB20: 44094 | BC20: 42866 | BD20: 55912 | BE20: 50140 | BF20: 47915 | BG20: 42197 | BH20: 34455 | BI20: 64298 | BJ20: 63127 | BK20: 57917 | BL20: 63389 | BM20: 50097 | BN20: 44081 | BO20: 46098 | BP20: 47957 | BQ20: 54089 | BR20: 61069 | BS20: 56360 | BT20: 43401 | BU20: 48089 | BV20: 64499 | BW20: 59863 | BX20: 65709 | BY20: 48802 | BZ20: 45155 | CA20: 53797 | CB20: 56948 | CC20: 52231 | CD20: 46512 | CE20: 49029 | CF20: 51118 | CG20: 46076 | CH20: 53071 | CI20: 49094 | CJ20: 42238 | CK20: 26230 | CL20: 15246 | CM20: 16113 | CN20: 17882 | CO20: 10892 | CP20: 21649 | CQ20: 31621 | CR20: 43175 | CS20: 48900 | CT20: 62819 | CU20: 53835 | CV20: 49148 | CW20: 36682 | CX20: 28933 | CY20: 28320 | CZ20: 30260 | DA20: 35676 | DB20: 40725 | DC20: 45324 | DD20: 41107 | DE20: 38268 | DF20: 53060 | DG20: 46139 | DH20: 45463 | DI20: 35312 | DJ20: 36307 | DK20: 28545 | DL20: 25097 | DM20: 32835 | DN20: 33356 | DO20: 35259 | DP20: 30900 | DQ20: 38662 | DR20: 53155 | DS20: 51083 | DT20: 52699 | DU20: 45468 | DV20: 46350 | DW20: 49680 | DX20: 53155 | DY20: 53434 | DZ20: 54873 | EA20: 54830 | EB20: 50227 | EC20: 38834 | ED20: 58044 | EE20: 61508 | EF20: 66194 | EG20: 58404 | EH20: 57796 | EI20: 58968 | EJ20: 57513 | EK20: 64134 | EL20: 45347 | EM20: 49899 | EN20: 60022 | EO20: 62333 | EP20: 64839 | EQ20: 64191 | ER20: 79448 | ES20: 68508 | ET20: 63209 | EU20: 70376 | EV20: 70278 | EW20: 46460 | EX20: 60388 | EY20: 76533 | EZ20: 67990 | FA20: 63279 | FB20: 81648 | FC20: 67486 | FD20: 49761 | FE20: 31971 | FF20: 31495 | FG20: 34072 | FH20: 33246 | FI20: 27680 | FJ20: 16760 | FK20: 24597 | FL20: 25179 | FM20: 48877 | FN20: 60680 | FO20: 63075 | FP20: 69520 | FR20: Addition
A21: Milk Intake (Million Litres) | B21: 49.27 | C21: 43.9 | D21: 48.61 | E21: 44.64 | F21: 42.99 | G21: 37.58 | H21: 39.91 | I21: 38.63 | J21: 37.22 | K21: 41.68 | L21: 43.37 | M21: 43 | N21: 47.1 | O21: 40.8 | P21: 38.8 | Q21: 41.8 | R21: 45.6 | S21: 45.7 | T21: 49.5 | U21: 46.4 | V21: 49.1 | W21: 50.3 | X21: 46.4 | Y21: 47.7 | Z21: 45.5 | AA21: 32.9 | AB21: 28.9 | AC21: 26 | AD21: 37.3 | AE21: 46.2 | AF21: 43.5 | AG21: 45.5 | AH21: 45.2 | AI21: 47.8 | AJ21: 48.6 | AK21: 47.9 | AL21: 49.32 | AM21: 42.48 | AN21: 40.28 | AO21: 44.43 | AP21: 50.62 | AQ21: 44.46 | AR21: 43.52 | AS21: 37.9 | AT21: 38.79 | AU21: 38.87 | AV21: 45.33 | AW21: 47.03 | AX21: 54.04 | AY21: 46.6 | AZ21: 49.26 | BA21: 45.01 | BB21: 43.56 | BC21: 44.47 | BD21: 40.52 | BE21: 41.76 | BF21: 41.66 | BG21: 43.52 | BH21: 44.32 | BI21: 45.32 | BJ21: 57.17 | BK21: 37.8 | BL21: 35.77 | BM21: 35.59 | BN21: 52.97 | BO21: 51.02 | BP21: 51.59 | BQ21: 50.94 | BR21: 51.66 | BS21: 55.42 | BT21: 68.28 | BU21: 58.87 | BV21: 56.8 | BW21: 52.83 | BX21: 48.41 | BY21: 54.35 | BZ21: 49.49 | CA21: 66.37 | CB21: 58.47 | CC21: 56.15 | CD21: 43.67 | CE21: 56.93 | CF21: 54.09 | CG21: 50.66 | CH21: 45.13 | CI21: 46.24 | CJ21: 38.64 | CK21: 47.09 | CL21: 47.24 | CM21: 48.87 | CN21: 42.55 | CO21: 54.95 | CP21: 55.81 | CQ21: 58.14 | CR21: 55.21 | CS21: 51.51 | CT21: 51.55 | CU21: 47.3 | CV21: 49.85 | CW21: 52.01 | CX21: 49.63 | CY21: 50.33 | CZ21: 53.18 | DA21: 52.56 | DB21: 56.37 | DC21: 55.25 | DD21: 57.02 | DE21: 68.15 | DF21: 68.07 | DG21: 54.66 | DH21: 54.33 | DI21: 41.46 | DJ21: 48.29 | DK21: 52.33 | DL21: 63.54 | DM21: 60.46 | DN21: 63.21 | DO21: 59.32 | DP21: 51.3 | DQ21: 68.91 | DR21: 63.39 | DS21: 53.88 | DT21: 56.09 | DU21: 48.61 | DV21: 49.36 | DW21: 53.24 | DX21: 54.31 | DY21: 59.31 | DZ21: 58.04 | EA21: 59.71 | EB21: 60.58 | EC21: 67.86 | ED21: 63.8 | EE21: 64.62 | EF21: 62.79 | EG21: 53.32 | EH21: 77.33 | EI21: 74.07 | EJ21: 69.49 | EK21: 67.75 | EL21: 72.04 | EM21: 66.59 | EN21: 65.22 | EO21: 64.89 | EP21: 69.36 | EQ21: 66.42 | ER21: 61.76 | ES21: 61.78 | ET21: 64.29 | EU21: 65.69 | EV21: 61.23 | EW21: 59.12 | EX21: 66.62 | EY21: 60.51 | EZ21: 58.31 | FA21: 59.27 | FB21: 62.09 | FC21: 52.21 | FD21: 52.19 | FE21: 59.49 | FF21: 73.78 | FG21: 71.69 | FH21: 71.23 | FI21: 71.48 | FJ21: 67.71 | FK21: 74.67 | FL21: 74.33 | FM21: 75.69 | FN21: 74.58 | FO21: 71.76 | FP21: 70.31 | FR21: Addition
A22: Cement Production (MT) | B22: 290805 | C22: 266889 | D22: 300610 | E22: 284987 | F22: 294158 | G22: 312176 | H22: 334444 | I22: 323478 | J22: 319464 | K22: 351963 | L22: 323447 | M22: 307385 | N22: 364432 | O22: 335247 | P22: 355858 | Q22: 363035 | R22: 376246 | S22: 365494 | T22: 393149 | U22: 405546 | V22: 407838 | W22: 361941 | X22: 364789 | Y22: 384853 | Z22: 350615 | AA22: 378453 | AB22: 397009 | AC22: 360540 | AD22: 381026 | AE22: 396951 | AF22: 398458 | AG22: 399873 | AH22: 382141 | AI22: 421579 | AJ22: 415866 | AK22: 357212 | AL22: 393921 | AM22: 380032 | AN22: 367673 | AO22: 365579 | AP22: 414161 | AQ22: 422519 | AR22: 454288 | AS22: 432938 | AT22: 453542 | AU22: 487594 | AV22: 464834 | AW22: 422048 | AX22: 454960 | AY22: 442636 | AZ22: 478416 | BA22: 468022 | BB22: 464695 | BC22: 464929 | BD22: 503428 | BE22: 492801 | BF22: 499479 | BG22: 553186 | BH22: 545041 | BI22: 492944 | BJ22: 511298 | BK22: 465471 | BL22: 550556 | BM22: 537452 | BN22: 516513 | BO22: 516185 | BP22: 570904 | BQ22: 553929 | BR22: 561235 | BS22: 557589 | BT22: 510747 | BU22: 486306 | BV22: 533490 | BW22: 531813 | BX22: 541438 | BY22: 568253 | BZ22: 585929 | CA22: 547238 | CB22: 575193 | CC22: 591612 | CD22: 528494 | CE22: 573034 | CF22: 584780 | CG22: 545956 | CH22: 565440 | CI22: 491307 | CJ22: 570522 | CK22: 535061 | CL22: 482762 | CM22: 513313 | CN22: 553631 | CO22: 451651 | CP22: 531067 | CQ22: 510140 | CR22: 489376 | CS22: 536021 | CT22: 523625 | CU22: 508648 | CV22: 510674 | CW22: 496527 | CX22: 464422 | CY22: 477053 | CZ22: 518656 | DA22: 538071 | DB22: 503641 | DC22: 504959 | DD22: 496346 | DE22: 487312 | DF22: 485178 | DG22: 470146 | DH22: 507037 | DI22: 501921 | DJ22: 486301 | DK22: 477432 | DL22: 527115 | DM22: 512470 | DN22: 519370 | DO22: 504615 | DP22: 479085 | DQ22: 496517 | DR22: 530404 | DS22: 548818 | DT22: 559424 | DU22: 509197 | DV22: 511961 | DW22: 594421 | DX22: 666341 | DY22: 712701 | DZ22: 707033 | EA22: 731253 | EB22: 668507 | EC22: 666855 | ED22: 669530 | EE22: 612980 | EF22: 721444 | EG22: 695953 | EH22: 717669 | EI22: 698424 | EJ22: 876998 | EK22: 896825 | EL22: 866344 | EM22: 892975 | EN22: 807553 | EO22: 791050 | EP22: 855883 | EQ22: 818496 | ER22: 911250 | ES22: 842239 | ET22: 752698 | EU22: 773153 | EV22: 804401 | EW22: 745559 | EX22: 829930 | EY22: 824474 | EZ22: 821765 | FA22: 774124 | FB22: 785773 | FC22: 724164 | FD22: 820772 | FE22: 745106 | FF22: 786702 | FG22: 794700 | FH22: 844237 | FI22: 872135 | FJ22: 834651 | FK22: 836384 | FL22: 813372 | FM22: 758055 | FR22: Addition
A23: Cement Consumption | B23: 264849 | C23: 178789 | D23: 223450 | E23: 258016 | F23: 250837 | G23: 274073 | H23: 273581 | I23: 284184 | J23: 253692 | K23: 309066 | L23: 281564 | M23: 252726 | N23: 364711 | O23: 291531 | P23: 289361 | Q23: 319710 | R23: 330084 | S23: 295465 | T23: 326414 | U23: 342284 | V23: 302720 | W23: 341277 | X23: 327859 | Y23: 339516 | Z23: 272261 | AA23: 330328 | AB23: 328259 | AC23: 308617 | AD23: 309501 | AE23: 329366 | AF23: 337295 | AG23: 339916 | AH23: 322912 | AI23: 365769 | AJ23: 382400 | AK23: 310639 | AL23: 342296 | AM23: 336756 | AN23: 279129 | AO23: 306196 | AP23: 337866 | AQ23: 361839 | AR23: 373767 | AS23: 373466 | AT23: 381272 | AU23: 407151 | AV23: 392733 | AW23: 374015 | AX23: 387809 | AY23: 354576 | AZ23: 420345 | BA23: 433787 | BB23: 458219 | BC23: 421855 | BD23: 422394 | BE23: 440336 | BF23: 441527 | BG23: 483033 | BH23: 487396 | BI23: 445404 | BJ23: 459227 | BK23: 417591 | BL23: 483218 | BM23: 480801 | BN23: 472675 | BO23: 465828 | BP23: 451461 | BQ23: 478011 | BR23: 518435 | BS23: 530913 | BT23: 480641 | BU23: 455345 | BV23: 472218 | BW23: 506914 | BX23: 493410 | BY23: 538118 | BZ23: 551501 | CA23: 505067 | CB23: 556244 | CC23: 559766 | CD23: 504639 | CE23: 552243 | CF23: 547359 | CG23: 514498 | CH23: 535018 | CI23: 460044 | CJ23: 537948 | CK23: 497821 | CL23: 441110 | CM23: 496172 | CN23: 527774 | CO23: 427594 | CP23: 506694 | CQ23: 488813 | CR23: 454727 | CS23: 484172 | CT23: 499260 | CU23: 495128 | CV23: 497791 | CW23: 475365 | CX23: 449160 | CY23: 470112 | CZ23: 511240 | DA23: 531119 | DB23: 499568 | DC23: 502719 | DD23: 494038 | DE23: 481880 | DF23: 483747 | DG23: 469809 | DH23: 505465 | DI23: 500357 | DJ23: 486637 | DK23: 466923 | DL23: 527771 | DM23: 510066 | DN23: 515953 | DO23: 499355 | DP23: 474075 | DQ23: 493176 | DR23: 528904 | DS23: 547543 | DT23: 551914 | DU23: 506800 | DV23: 509698 | DW23: 591799 | DX23: 659798 | DY23: 691588 | DZ23: 677381 | EA23: 723124 | EB23: 662609 | EC23: 661504 | ED23: 663795 | EE23: 606204 | EF23: 715968 | EG23: 684497 | EH23: 707536 | EI23: 685697 | EJ23: 861938 | EK23: 879063 | EL23: 856980 | EM23: 870442 | EN23: 788229 | EO23: 778088 | EP23: 845087 | EQ23: 798007 | ER23: 877874 | ES23: 819889 | ET23: 717566 | EU23: 745289 | EV23: 778142 | EW23: 717267 | EX23: 799592 | EY23: 800673 | EZ23: 797912 | FA23: 752852 | FB23: 746930 | FC23: 696436 | FD23: 790844 | FE23: 718119 | FF23: 745702 | FG23: 763758 | FH23: 803562 | FI23: 833772 | FJ23: 802414 | FK23: 789900 | FL23: 786042 | FM23: 724307 | FR23: Addition
A24: Soft drinks Production ('000 Litres) | B24: 29405 | C24: 31178 | D24: 33984 | E24: 29352 | F24: 29445 | G24: 29588 | H24: 29332 | I24: 28525 | J24: 29593 | K24: 30435 | L24: 29333 | M24: 31163 | N24: 34446 | O24: 32457 | P24: 36156 | Q24: 31162 | R24: 26622 | S24: 28910 | T24: 28478 | U24: 28580 | V24: 29674 | W24: 28540 | X24: 27366 | Y24: 38962 | Z24: 34317 | AA24: 32009 | AB24: 37363 | AC24: 29331 | AD24: 24359 | AE24: 27391 | AF24: 22073 | AG24: 24458 | AH24: 31113 | AI24: 32540 | AJ24: 31497 | AK24: 33067 | AL24: 32809 | AM24: 36068 | AN24: 42552 | AO24: 27345 | AP24: 27581 | AQ24: 30919 | AR24: 28464 | AS24: 27697 | AT24: 36026 | AU24: 34810 | AV24: 36272 | AW24: 43438 | AX24: 39007 | AY24: 39146 | AZ24: 40320 | BA24: 37885 | BB24: 40430 | BC24: 28706 | BD24: 33790 | BE24: 33404 | BF24: 35899 | BG24: 41601 | BH24: 40134 | BI24: 49142 | BJ24: 41348 | BK24: 41440 | BL24: 48865 | BM24: 42148 | BN24: 36874 | BO24: 36274 | BP24: 32086 | BQ24: 38432 | BR24: 40176 | BS24: 42936 | BT24: 40025 | BU24: 49966 | BV24: 41348 | BW24: 41440 | BX24: 48865 | BY24: 42148 | BZ24: 36874 | CA24: 36202 | CB24: 32158 | CC24: 38508 | CD24: 40291 | CE24: 43203 | CF24: 40141 | CG24: 49966 | CH24: 50409 | CI24: 43353 | CJ24: 50623 | CK24: 46399 | CL24: 40742 | CM24: 45875 | CN24: 41980 | CO24: 41217 | CP24: 40221 | CQ24: 45275 | CR24: 45073 | CS24: 66378 | CT24: 52062 | CU24: 49685 | CV24: 52580 | CW24: 45690 | CX24: 41482 | CY24: 44827 | CZ24: 43725 | DA24: 48795 | DB24: 45956 | DC24: 46546 | DD24: 50201 | DE24: 54021 | DF24: 53585 | DG24: 55218 | DH24: 61413 | DI24: 58230 | DJ24: 53086 | DK24: 46074 | DL24: 47149 | DM24: 49248 | DN24: 53234 | DO24: 47586 | DP24: 50715 | DQ24: 55398 | DR24: 52654 | DS24: 42072 | DT24: 52109 | DU24: 35951 | DV24: 34129 | DW24: 47273 | DX24: 39833 | DY24: 39290 | DZ24: 52436 | EA24: 47215 | EB24: 42916 | EC24: 64707 | ED24: 50153 | EE24: 42749 | EF24: 53157 | EG24: 43742 | EH24: 38327 | EI24: 46518 | EJ24: 33864 | EK24: 42744 | EL24: 53923 | EM24: 52394 | EN24: 55226 | EO24: 57993 | EP24: 46537 | EQ24: 44407 | ER24: 61898 | ES24: 45868 | ET24: 44289 | EU24: 45640 | EV24: 35855 | EW24: 38842 | EX24: 50841 | EY24: 50393 | EZ24: 52363 | FA24: 62536 | FB24: 52601 | FC24: 47725 | FD24: 56068 | FE24: 40314 | FF24: 36206 | FG24: 41653 | FH24: 32393 | FI24: 36511 | FJ24: 56434 | FK24: 48602 | FL24: 53069 | FM24: 78974 | FR24: Addition
A25: Production of Assembled Vehicles | B25: 299 | C25: 521 | D25: 510 | E25: 438 | F25: 521 | G25: 550 | H25: 509 | I25: 460 | J25: 461 | K25: 460 | L25: 490 | M25: 502 | N25: 290 | O25: 413 | P25: 462 | Q25: 449 | R25: 554 | S25: 550 | T25: 524 | U25: 553 | V25: 651 | W25: 660 | X25: 594 | Y25: 349 | Z25: 387 | AA25: 588 | AB25: 303 | AC25: 594 | AD25: 654 | AE25: 588 | AF25: 570 | AG25: 588 | AH25: 597 | AI25: 585 | AJ25: 420 | AK25: 344 | AL25: 435 | AM25: 536 | AN25: 496 | AO25: 584 | AP25: 560 | AQ25: 609 | AR25: 617 | AS25: 578 | AT25: 590 | AU25: 652 | AV25: 733 | AW25: 558 | AX25: 511 | AY25: 792 | AZ25: 737 | BA25: 798 | BB25: 832 | BC25: 856 | BD25: 809 | BE25: 828 | BF25: 886 | BG25: 887 | BH25: 724 | BI25: 586 | BJ25: 601 | BK25: 949 | BL25: 922 | BM25: 813 | BN25: 827 | BO25: 745 | BP25: 757 | BQ25: 931 | BR25: 1029 | BS25: 1139 | BT25: 972 | BU25: 496 | BV25: 363 | BW25: 587 | BX25: 650 | BY25: 658 | BZ25: 642 | CA25: 482 | CB25: 491 | CC25: 605 | CD25: 623 | CE25: 357 | CF25: 461 | CG25: 376 | CH25: 276 | CI25: 578 | CJ25: 645 | CK25: 436 | CL25: 434 | CM25: 323 | CN25: 483 | CO25: 302 | CP25: 351 | CQ25: 370 | CR25: 364 | CS25: 322 | CT25: 395 | CU25: 529 | CV25: 548 | CW25: 409 | CX25: 407 | CY25: 366 | CZ25: 587 | DA25: 434 | DB25: 606 | DC25: 569 | DD25: 476 | DE25: 327 | DF25: 431 | DG25: 614 | DH25: 633 | DI25: 739 | DJ25: 732 | DK25: 556 | DL25: 648 | DM25: 709 | DN25: 595 | DO25: 728 | DP25: 872 | DQ25: 545 | DR25: 614 | DS25: 861 | DT25: 830 | DU25: 669 | DV25: 659 | DW25: 415 | DX25: 735 | DY25: 595 | DZ25: 591 | EA25: 676 | EB25: 533 | EC25: 547 | ED25: 560 | EE25: 565 | EF25: 705 | EG25: 737 | EH25: 609 | EI25: 576 | EJ25: 798 | EK25: 962 | EL25: 1173 | EM25: 1138 | EN25: 968 | EO25: 1198 | EP25: 925 | EQ25: 1263 | ER25: 1245 | ES25: 1348 | ET25: 1483 | EU25: 1186 | EV25: 1246 | EW25: 1036 | EX25: 1320 | EY25: 1004 | EZ25: 798 | FA25: 619 | FB25: 1135 | FC25: 980 | FD25: 1214 | FE25: 972 | FF25: 1258 | FG25: 1123 | FH25: 832 | FI25: 1181 | FJ25: 1262 | FK25: 774 | FL25: 874 | FM25: 811 | FR25: Addition
A26: Galvanized sheets Production (MT) | B26: 14254 | C26: 13700 | D26: 20095 | E26: 18929 | F26: 18842 | G26: 16006 | H26: 16790 | I26: 16457 | J26: 16299 | K26: 18488 | L26: 16219 | M26: 15331 | N26: 22094 | O26: 22386 | P26: 22928 | Q26: 20957 | R26: 24744 | S26: 24677 | T26: 24906 | U26: 24659 | V26: 17988 | W26: 16619 | X26: 22104 | Y26: 24033 | Z26: 22940 | AA26: 19655 | AB26: 21507 | AC26: 20892 | AD26: 22197 | AE26: 17180 | AF26: 21411 | AG26: 23040 | AH26: 23268 | AI26: 20473 | AJ26: 21969 | AK26: 21283 | AL26: 25528 | AM26: 22874 | AN26: 26296 | AO26: 26010 | AP26: 23866 | AQ26: 26147 | AR26: 25007 | AS26: 27398 | AT26: 25051 | AU26: 27588 | AV26: 26628 | AW26: 23706 | AX26: 22090 | AY26: 18573 | AZ26: 21267 | BA26: 25989 | BB26: 27433 | BC26: 24465 | BD26: 21779 | BE26: 25753 | BF26: 26126 | BG26: 26732 | BH26: 25763 | BI26: 18539 | BJ26: 21304 | BK26: 20078 | BL26: 22797 | BM26: 20674 | BN26: 23132 | BO26: 20358 | BP26: 18415 | BQ26: 20871 | BR26: 20581 | BS26: 26024 | BT26: 25764 | BU26: 16938 | BV26: 21330 | BW26: 20102 | BX26: 20120 | BY26: 23109 | BZ26: 21980 | CA26: 20180 | CB26: 18320 | CC26: 24190 | CD26: 21045 | CE26: 18328 | CF26: 19143 | CG26: 19431 | CH26: 26230 | CI26: 22994 | CJ26: 22574 | CK26: 23225 | CL26: 23081 | CM26: 15424 | CN26: 22640 | CO26: 15296 | CP26: 24188 | CQ26: 21312 | CR26: 24357 | CS26: 21438 | CT26: 23919 | CU26: 21890 | CV26: 22048 | CW26: 21434 | CX26: 22271 | CY26: 21434 | CZ26: 22510 | DA26: 21847 | DB26: 22425 | DC26: 23906 | DD26: 22877 | DE26: 21266 | DF26: 20124 | DG26: 22749 | DH26: 26313 | DI26: 23214 | DJ26: 22501 | DK26: 24667 | DL26: 23260 | DM26: 21918 | DN26: 22641 | DO26: 22619 | DP26: 21871 | DQ26: 22547 | DR26: 23397 | DS26: 21989 | DT26: 18527 | DU26: 6259 | DV26: 18042 | DW26: 23730 | DX26: 24493 | DY26: 23226 | DZ26: 20801 | EA26: 22868 | EB26: 23268 | EC26: 20854 | ED26: 18631 | EE26: 20762 | EF26: 21781 | EG26: 21572 | EH26: 21165 | EI26: 22365 | EJ26: 20432 | EK26: 19744 | EL26: 17581 | EM26: 20111 | EN26: 25926 | EO26: 20348 | EP26: 21546 | EQ26: 21671 | ER26: 19616 | ES26: 19479 | ET26: 23383 | EU26: 22073 | EV26: 20895 | EW26: 17064 | EX26: 21833 | EY26: 19951 | EZ26: 20589 | FA26: 17686 | FB26: 17350 | FC26: 22457 | FD26: 22373 | FE26: 21404 | FF26: 23555 | FG26: 21100 | FH26: 24337 | FI26: 23943 | FJ26: 23443 | FK26: 24178 | FL26: 23847 | FM26: 24555 | FR26: Addition
A27: Energy
A28: Hydropower Generation (KWh Million) | X28: 263.04 | Y28: 331.37 | Z28: 329.53 | AA28: 331.64 | AB28: 292.5 | AC28: 272.88 | AD28: 323.37 | AE28: 341.75 | AF28: 358.34 | AG28: 347.5 | AH28: 333.73 | AI28: 359.87 | AJ28: 372.05 | AK28: 368.75 | AL28: 377.24 | AM28: 332.99 | AN28: 347.6 | AO28: 345.05 | AP28: 376.96 | AQ28: 378.41 | AR28: 385.86 | AS28: 376.91 | AT28: 263.41 | AU28: 384.52 | AV28: 357.67 | AW28: 346.51 | AX28: 339.2 | AY28: 269.93 | AZ28: 286.74 | BA28: 307.53 | BB28: 250.18 | BC28: 263.41 | BD28: 253.87 | BE28: 293.87 | BF28: 277.62 | BG28: 279.02 | BH28: 307.25 | BI28: 282.25 | BJ28: 278.24 | BK28: 229.5 | BL28: 246.01 | BM28: 264.24 | BN28: 301.03 | BO28: 297.28 | BP28: 305.24 | BQ28: 318.62 | BR28: 306.34 | BS28: 310 | BT28: 300.19 | BU28: 306.66 | BV28: 322.49 | BW28: 296.75 | BX28: 334.51 | BY28: 303.46 | BZ28: 334.37 | CA28: 348.09 | CB28: 336.92 | CC28: 363.61 | CD28: 348.63 | CE28: 356.88 | CF28: 314.93 | CG28: 299.08 | CH28: 252.44 | CI28: 213.9 | CJ28: 234.26 | CK28: 211.55 | CL28: 228.56 | CM28: 180.22 | CN28: 192.56 | CO28: 251.3 | CP28: 239.47 | CQ28: 216.98 | CR28: 305.16 | CS28: 250.42 | CT28: 222.95 | CU28: 193.43 | CV28: 248.39 | CW28: 316.85 | CX28: 385.88 | CY28: 400.86 | CZ28: 420.32 | DA28: 417.37 | DB28: 392.07 | DC28: 365.42 | DD28: 340.07 | DE28: 282.78 | DF28: 278.92 | DG28: 253.91 | DH28: 282.83 | DI28: 191.99 | DJ28: 242.63 | DK28: 272.42 | DL28: 268.91 | DM28: 251.48 | DN28: 233.8 | DO28: 268.4 | DP28: 299.19 | DQ28: 360.88 | DR28: 357.69 | DS28: 341.94 | DT28: 359.11 | DU28: 297.63 | DV28: 319.47 | DW28: 334.17 | DX28: 357.84 | DY28: 357.69 | DZ28: 355.75 | EA28: 373.09 | EB28: 385.05 | EC28: 400.31 | ED28: 330.31 | EE28: 281.4 | EF28: 305.11 | EG28: 307.93 | EH28: 369.02 | EI28: 317.99 | EJ28: 285.79 | EK28: 274.03 | EL28: 261.68 | EM28: 309.26 | EN28: 293.33 | EO28: 339.13 | EP28: 320.3 | EQ28: 244.23 | ER28: 243.2 | ES28: 228.86 | ET28: 284.04 | EU28: 264.86 | EV28: 252.39 | EW28: 256.76 | EX28: 243.89 | EY28: 247.42 | EZ28: 233.02 | FA28: 220.92 | FB28: 185.2 | FC28: 112.91 | FD28: 125.98 | FE28: 190.85 | FF28: 237.88 | FG28: 257.94 | FH28: 279.48 | FI28: 258.71 | FJ28: 247.2 | FK28: 205.28 | FL28: 287.58 | FM28: 273.64 | FN28: 254.51 | FO28: 261.66 | FP28: 291.1 | FR28: Addition
A29: Geothermal Generation (KWh Million) | X29: 115.04 | Y29: 125.38 | Z29: 128.54 | AA29: 125.38 | AB29: 133.99 | AC29: 124.26 | AD29: 131.96 | AE29: 128.84 | AF29: 119.2 | AG29: 121.97 | AH29: 128.27 | AI29: 128.86 | AJ29: 120.86 | AK29: 130.03 | AL29: 129.45 | AM29: 113.11 | AN29: 134.93 | AO29: 151.9 | AP29: 158.56 | AQ29: 162.04 | AR29: 157.34 | AS29: 157.52 | AT29: 152.74 | AU29: 151.05 | AV29: 151 | AW29: 160.87 | AX29: 178.92 | AY29: 145.48 | AZ29: 170.77 | BA29: 169.88 | BB29: 190.75 | BC29: 220.91 | BD29: 257.71 | BE29: 246.67 | BF29: 293.26 | BG29: 339.4 | BH29: 322.17 | BI29: 381.56 | BJ29: 388.4 | BK29: 352.12 | BL29: 376.67 | BM29: 359.47 | BN29: 379.97 | BO29: 362.3 | BP29: 353.06 | BQ29: 377.56 | BR29: 388.99 | BS29: 402.15 | BT29: 392.55 | BU29: 387.45 | BV29: 392 | BW29: 391.65 | BX29: 383.11 | BY29: 394.48 | BZ29: 403.45 | CA29: 341.92 | CB29: 392.99 | CC29: 345 | CD29: 335.37 | CE29: 363.93 | CF29: 369.05 | CG29: 371.24 | CH29: 380.15 | CI29: 354.16 | CJ29: 387.87 | CK29: 381.13 | CL29: 393.84 | CM29: 376.2 | CN29: 401.65 | CO29: 415.03 | CP29: 402.65 | CQ29: 416.05 | CR29: 411.39 | CS29: 436.21 | CT29: 430.49 | CU29: 387.02 | CV29: 448.12 | CW29: 427.73 | CX29: 447.05 | CY29: 430 | CZ29: 438.12 | DA29: 426.57 | DB29: 439.8 | DC29: 432.03 | DD29: 397.58 | DE29: 423.32 | DF29: 417.35 | DG29: 374.43 | DH29: 445.1 | DI29: 397.66 | DJ29: 427.38 | DK29: 413.44 | DL29: 440.3 | DM29: 425.46 | DN29: 453.93 | DO29: 493.56 | DP29: 481.9 | DQ29: 464.14 | DR29: 476.6 | DS29: 430.73 | DT29: 460.27 | DU29: 411.76 | DV29: 391.79 | DW29: 421.44 | DX29: 433.46 | DY29: 423.59 | DZ29: 380.7 | EA29: 440.13 | EB29: 396.82 | EC29: 392.5 | ED29: 464.78 | EE29: 422.15 | EF29: 460.68 | EG29: 424.54 | EH29: 385.38 | EI29: 408.96 | EJ29: 463.16 | EK29: 452.79 | EL29: 439.81 | EM29: 387.8 | EN29: 378.49 | EO29: 348.5 | EP29: 310.79 | EQ29: 304.77 | ER29: 410.35 | ES29: 441.39 | ET29: 521.44 | EU29: 493.85 | EV29: 520.69 | EW29: 513.48 | EX29: 487.63 | EY29: 478.09 | EZ29: 494.27 | FA29: 540.8 | FB29: 524.82 | FC29: 472.15 | FD29: 509.36 | FE29: 476.33 | FF29: 510.83 | FG29: 504.57 | FH29: 494.81 | FI29: 522.92 | FJ29: 511.88 | FK29: 509.54 | FL29: 495.19 | FM29: 497.69 | FN29: 506.91 | FO29: 446.76 | FP29: 442.68 | FR29: Addition
A30: Thermal Generation (KWh Million) | X30: 208.43 | Y30: 155.77 | Z30: 168.89 | AA30: 159.01 | AB30: 193.65 | AC30: 175.14 | AD30: 159.32 | AE30: 147.3 | AF30: 168.06 | AG30: 175.59 | AH30: 165.68 | AI30: 165.67 | AJ30: 159.4 | AK30: 152.34 | AL30: 168.67 | AM30: 160.26 | AN30: 162.56 | AO30: 139.85 | AP30: 132.96 | AQ30: 130.79 | AR30: 157.34 | AS30: 181.74 | AT30: 177.94 | AU30: 214.97 | AV30: 224.4 | AW30: 197.82 | AX30: 228.8 | AY30: 258.38 | AZ30: 280.34 | BA30: 239.78 | BB30: 295.89 | BC30: 245.8 | BD30: 251.5 | BE30: 224.2 | BF30: 163.91 | BG30: 156.66 | BH30: 121.53 | BI30: 93.78 | BJ30: 109.19 | BK30: 121.11 | BL30: 134.19 | BM30: 120.77 | BN30: 103.09 | BO30: 109.11 | BP30: 142.9 | BQ30: 111.57 | BR30: 99 | BS30: 99.67 | BT30: 88.88 | BU30: 92.11 | BV30: 93.03 | BW30: 95.42 | BX30: 112.23 | BY30: 101.92 | BZ30: 92.2 | CA30: 113.36 | CB30: 109.74 | CC30: 137.77 | CD30: 136.75 | CE30: 135.24 | CF30: 158.05 | CG30: 157.85 | CH30: 197.05 | CI30: 182.35 | CJ30: 229.61 | CK30: 222.97 | CL30: 223.54 | CM30: 274.2 | CN30: 271.3 | CO30: 159.47 | CP30: 213.32 | CQ30: 223.83 | CR30: 153.1 | CS30: 183.66 | CT30: 242.34 | CU30: 249.13 | CV30: 202.18 | CW30: 138.66 | CX30: 82.92 | CY30: 82.37 | CZ30: 86.86 | DA30: 117.23 | DB30: 85.33 | DC30: 87.21 | DD30: 80.15 | DE30: 91.53 | DF30: 114.07 | DG30: 98.56 | DH30: 99 | DI30: 181.14 | DJ30: 110.34 | DK30: 146.23 | DL30: 133.41 | DM30: 131.77 | DN30: 104.77 | DO30: 69.51 | DP30: 62.44 | DQ30: 62.18 | DR30: 54.51 | DS30: 53.83 | DT30: 55.65 | DU30: 35.75 | DV30: 56.3 | DW30: 61.87 | DX30: 60.63 | DY30: 70.5 | DZ30: 89.46 | EA30: 79.51 | EB30: 59.65 | EC30: 77.37 | ED30: 74.69 | EE30: 105.51 | EF30: 63.08 | EG30: 59.6 | EH30: 116.17 | EI30: 84.17 | EJ30: 122.59 | EK30: 109.35 | EL30: 107.24 | EM30: 117.64 | EN30: 134.91 | EO30: 167.26 | EP30: 206.26 | EQ30: 223.97 | ER30: 170.16 | ES30: 125.82 | ET30: 79.71 | EU30: 83.1 | EV30: 104.36 | EW30: 120.54 | EX30: 118.11 | EY30: 96.53 | EZ30: 123.62 | FA30: 132.92 | FB30: 107.32 | FC30: 142.35 | FD30: 166.86 | FE30: 119.53 | FF30: 95.38 | FG30: 68.13 | FH30: 108.29 | FI30: 89.58 | FJ30: 130.18 | FK30: 140.57 | FL30: 67.93 | FM30: 69.55 | FN30: 90.65 | FO30: 74.57 | FP30: 79.31 | FR30: Addition
A31: Wind Generation (KWh Million) | BV31: 5.01 | BW31: 6.73 | BX31: 6.71 | BY31: 4.22 | BZ31: 2.42 | CA31: 2.06 | CB31: 1.84 | CC31: 3.71 | CD31: 3.75 | CE31: 5.77 | CF31: 6.18 | CG31: 8.02 | CH31: 6.98 | CI31: 7.46 | CJ31: 6.32 | CK31: 6.59 | CL31: 3.48 | CM31: 3.09 | CN31: 1.47 | CO31: 3.34 | CP31: 3.57 | CQ31: 4.28 | CR31: 7.13 | CS31: 7.28 | CT31: 3.26 | CU31: 6.86 | CV31: 4.11 | CW31: 3.24 | CX31: 1.7 | CY31: 1.23 | CZ31: 1.69 | DA31: 2.52 | DB31: 7.46 | DC31: 76.86 | DD31: 133.4 | DE31: 133.26 | DF31: 147.55 | DG31: 146.21 | DH31: 144 | DI31: 142.21 | DJ31: 164.12 | DK31: 92.38 | DL31: 124.89 | DM31: 151.43 | DN31: 152.91 | DO31: 137.42 | DP31: 114.03 | DQ31: 45.57 | DR31: 89.7 | DS31: 100.16 | DT31: 85.88 | DU31: 88.03 | DV31: 105.62 | DW31: 88.45 | DX31: 110.42 | DY31: 118.62 | DZ31: 139.82 | EA31: 121.83 | EB31: 147.84 | EC31: 134.98 | ED31: 137.65 | EE31: 109.84 | EF31: 199.92 | EG31: 164.71 | EH31: 130.21 | EI31: 184.61 | EJ31: 152.69 | EK31: 190.07 | EL31: 187.06 | EM31: 200.91 | EN31: 195.68 | EO31: 131.45 | EP31: 156.28 | EQ31: 123.29 | ER31: 201.76 | ES31: 179.24 | ET31: 152.76 | EU31: 181.07 | EV31: 208.4 | EW31: 185.7 | EX31: 200.56 | EY31: 237.49 | EZ31: 177.13 | FA31: 139.35 | FB31: 203.31 | FC31: 190.65 | FD31: 152.35 | FE31: 157 | FF31: 181.72 | FG31: 168.06 | FH31: 198.46 | FI31: 186.66 | FJ31: 141.3 | FK31: 183.36 | FL31: 159.76 | FM31: 85.5 | FN31: 136.13 | FO31: 156.14 | FP31: 198.72 | FR31: Addition
A32: Solar Generation (KWh Million) | CT32: 0 | CU32: 0 | CV32: 0 | CW32: 0 | CX32: 0.02 | CY32: 0.01 | CZ32: 0 | DA32: 0.01 | DB32: 0.01 | DC32: 0.01 | DD32: 5.77 | DE32: 7.79 | DF32: 7.99 | DG32: 7.02 | DH32: 8.07 | DI32: 8.19 | DJ32: 7.91 | DK32: 7.07 | DL32: 7.09 | DM32: 7.44 | DN32: 7.91 | DO32: 8.05 | DP32: 7.84 | DQ32: 7.58 | DR32: 7.59 | DS32: 6.94 | DT32: 7.8 | DU32: 7.75 | DV32: 7.89 | DW32: 6.96 | DX32: 6.78 | DY32: 6.68 | DZ32: 6.79 | EA32: 8.16 | EB32: 7.59 | EC32: 7.1 | ED32: 7.44 | EE32: 6.97 | EF32: 7.77 | EG32: 7.41 | EH32: 7.59 | EI32: 7.41 | EJ32: 13.06 | EK32: 17.02 | EL32: 18.24 | EM32: 23.43 | EN32: 23.04 | EO32: 27.85 | EP32: 32.41 | EQ32: 30.09 | ER32: 35.14 | ES32: 31.04 | ET32: 33.21 | EU32: 28.2 | EV32: 24.71 | EW32: 22.43 | EX32: 26.32 | EY32: 38.77 | EZ32: 38.81 | FA32: 42.41 | FB32: 46.69 | FC32: 42.85 | FD32: 40.59 | FE32: 39.41 | FF32: 44.28 | FG32: 36.66 | FH32: 37.9 | FI32: 40.85 | FJ32: 39.25 | FK32: 42.87 | FL32: 35.69 | FM32: 44.44 | FN32: 38.28 | FO32: 39.82 | FP32: 40.17 | FR32: Addition
A33: Total Consumption of Electricity (KWh Million) | CT33: =SUM(CT28:CT32) -> 899.04 | CU33: =SUM(CU28:CU32) -> 836.44 | CV33: =SUM(CV28:CV32) -> 902.8 | CW33: =SUM(CW28:CW32) -> 886.48 | CX33: =SUM(CX28:CX32) -> 917.57 | CY33: =SUM(CY28:CY32) -> 914.47 | CZ33: =SUM(CZ28:CZ32) -> 946.99 | DA33: =SUM(DA28:DA32) -> 963.7 | ... FP33: =SUM(FP28:FP32) -> 1051.98 | FR33: Addition
A34: Murban ADNOC Crude Oil Prices (US$/ BBL) | B34: 77.5 | C34: 74.2 | D34: 78.3 | E34: 84.8 | F34: 77.85 | G34: 74.8 | H34: 73 | I34: 74.6 | J34: 75.9 | K34: 81.5 | L34: 85.65 | M34: 91.85 | N34: 95.55 | O34: 103.6 | P34: 112.55 | Q34: 120.7 | R34: 113.6 | S34: 112.15 | T34: 113.95 | U34: 109.05 | V34: 110.9 | W34: 108.95 | X34: 114.35 | Y34: 111.8 | Z34: 114.2 | AA34: 120.45 | AB34: 127 | AC34: 121.2 | AD34: 110.6 | AE34: 97.35 | AF34: 101.75 | AG34: 111.65 | AH34: 115.4 | AI34: 113.2 | AJ34: 112.1 | AK34: 110.75 | AL34: 112.05 | AM34: 115.4 | AN34: 109.95 | AO34: 105.65 | AP34: 103.65 | AQ34: 103 | AR34: 106.85 | AS34: 111.7 | AT34: 114.5 | AU34: 112.45 | AV34: 112.2 | AW34: 113.85 | AX34: 109.75 | AY34: 109.95 | AZ34: 108.3 | BA34: 107.95 | BB34: 109.15 | BC34: 111.65 | BD34: 109.5 | BE34: 104.25 | BF34: 97.95 | BG34: 87.35 | BH34: 77 | BI34: 60.65 | BJ34: 46.4 | BK34: 56.55 | BL34: 56.1 | BM34: 60.55 | BN34: 65.75 | BO34: 63.7 | BP34: 57.7 | BQ34: 48.85 | BR34: 46.6 | BS34: 47.3 | BT34: 43.55 | BU34: 37.25 | BV34: 29.95 | BW34: 33 | BX34: 38.2 | BY34: 42 | BZ34: 47.35 | CA34: 49.05 | CB34: 44.6 | CC34: 48.85 | CD34: 45.5 | CE34: 51.35 | CF34: 46.15 | CG34: 54.15 | CH34: 55.35 | CI34: 56.1 | CJ34: 52.6 | CK34: 53.4 | CL34: 51.45 | CM34: 47.3 | CN34: 48.6 | CO34: 48.85 | CP34: 55.7 | CQ34: 63.83 | CR34: 63.65 | CS34: 62.06 | CT34: 66.28 | CU34: 65.98 | CV34: 66.31 | CW34: 70.97 | CX34: 76.71 | CY34: 73.22 | CZ34: 76 | DA34: 74.91 | DB34: 78.75 | DC34: 81.28 | DD34: 68.05 | DE34: 59.33 | DF34: 60.81 | DG34: 65.64 | DH34: 68.6 | DI34: 73.05 | DJ34: 69.7 | DK34: 62.75 | DL34: 64.86 | DM34: 60.16 | DN34: 62.39 | DO34: 60.88 | DP34: 63.48 | DQ34: 66.66 | DR34: 66.09 | DS34: 55.53 | DT34: 33.92 | DU34: 17.66 | DV34: 25.17 | DW34: 37.05 | DX34: 43.42 | DY34: 45.19 | DZ34: 41.54 | EA34: 40.08 | EB34: 42.61 | EC34: 49.17 | ED34: 54.38 | EE34: 61.05 | EF34: 64.56 | EG34: 63.24 | EH34: 66.91 | EI34: 71.89 | EJ34: 73.53 | EK34: 70.33 | EL34: 73.88 | EM34: 82.11 | EN34: 80.37 | EO34: 74.38 | EP34: 85.41 | EQ34: 93.95 | ER34: 113.48 | ES34: 105.64 | ET34: 113.87 | EU34: 117.72 | EV34: 108.55 | EW34: 101.9 | EX34: 95.32 | EY34: 93.62 | EZ34: 89.73 | FA34: 79.61 | FB34: 81.62 | FC34: 81.88 | FD34: 78.45 | FE34: 84.13 | FF34: 75.82 | FG34: 75.19 | FH34: 81.06 | FI34: 87.33 | FJ34: 94.6 | FK34: 91.78 | FL34: 84.92 | FM34: 79 | FN34: 80.04 | FO34: 81.23 | FP34: 84.22 | FR34: Average
